<?xml version="1.0" encoding="UTF-8"?>
<sdf version='1.9'>
  <model name='phobos'>
    <pose>0 0 0.142131 0 0 0</pose>
    <self_collide>false</self_collide>
    <static>false</static>
    <link name="base_link">
      <inertial>
        <mass>5.14</mass>
        <pose>0 0 0 0 0 3.14</pose>
        <!-- enter the inertia values for the fuselage here, about the COM of the drone -->
        <inertia>
          <ixx>0.059159487</ixx>
          <ixy>0.000202606</ixy>
          <ixz>0.003988761</ixz>
          <iyy>0.063596644</iyy>
          <iyz>0.000386736</iyz>
          <izz>0.105411543</izz>
        </inertia>
      </inertial>
      <enable_wind>true</enable_wind>
      <gravity>true</gravity>
      <velocity_decay/>
      <visual name="base_link_visual">
        <pose>0 0 0 0 0 0</pose>
        <geometry>
          <mesh>
            <scale>1 1 1</scale>
            <uri>model://phobos/meshes/phobos_compressed.stl</uri>
          </mesh>
        </geometry>
      </visual>
      <collision name="base_link_collision">
        <!-- <pose>0 0 -0.2 0 0 0</pose> -->
        <geometry>
          <mesh>
            <scale>1 1 1</scale>
            <uri>model://phobos/meshes/phobos_compressed.stl</uri>
          </mesh>
        </geometry>
        <!-- <geometry>
          <box>
            <size>2 2 0.46</size>
          </box>
        </geometry> -->
        <surface>
          <contact>
            <ode>
              <kp>100000</kp>
              <kd>1.0</kd>
              <max_vel>0.1</max_vel>
              <min_depth>0.001</min_depth>
            </ode>
          </contact>
          <friction>
            <ode/>
          </friction>
        </surface>
      </collision>
      <sensor name="air_pressure_sensor" type="air_pressure">
        <always_on>1</always_on>
        <update_rate>50</update_rate>
        <air_pressure>
          <pressure>
            <noise type="gaussian">
              <mean>0</mean>
              <stddev>0.01</stddev>
            </noise>
          </pressure>
        </air_pressure>
      </sensor>
      <sensor name="imu_sensor" type="imu">
        <always_on>1</always_on>
        <update_rate>250</update_rate>
        <imu>
          <angular_velocity>
            <x>
              <noise type="gaussian">
                <mean>0</mean>
                <stddev>0.00018665</stddev>
                <dynamic_bias_stddev>3.8785e-05</dynamic_bias_stddev>
                <dynamic_bias_correlation_time>1000</dynamic_bias_correlation_time>
              </noise>
            </x>
            <y>
              <noise type="gaussian">
                <mean>0</mean>
                <stddev>0.00018665</stddev>
                <dynamic_bias_stddev>3.8785e-05</dynamic_bias_stddev>
                <dynamic_bias_correlation_time>1000</dynamic_bias_correlation_time>
              </noise>
            </y>
            <z>
              <noise type="gaussian">
                <mean>0</mean>
                <stddev>0.00018665</stddev>
                <dynamic_bias_stddev>3.8785e-05</dynamic_bias_stddev>
                <dynamic_bias_correlation_time>1000</dynamic_bias_correlation_time>
              </noise>
            </z>
          </angular_velocity>
          <linear_acceleration>
            <x>
              <noise type="gaussian">
                <mean>0</mean>
                <stddev>0.00186</stddev>
                <dynamic_bias_stddev>0.006</dynamic_bias_stddev>
                <dynamic_bias_correlation_time>300</dynamic_bias_correlation_time>
              </noise>
            </x>
            <y>
              <noise type="gaussian">
                <mean>0</mean>
                <stddev>0.00186</stddev>
                <dynamic_bias_stddev>0.006</dynamic_bias_stddev>
                <dynamic_bias_correlation_time>300</dynamic_bias_correlation_time>
              </noise>
            </y>
            <z>
              <noise type="gaussian">
                <mean>0</mean>
                <stddev>0.00186</stddev>
                <dynamic_bias_stddev>0.006</dynamic_bias_stddev>
                <dynamic_bias_correlation_time>300</dynamic_bias_correlation_time>
              </noise>
            </z>
          </linear_acceleration>
        </imu>
      </sensor>
      <sensor name="navsat_sensor" type="navsat">
        <always_on>1</always_on>
        <update_rate>30</update_rate>
      </sensor>
    </link>
    <link name="rotor_0">
      <gravity>true</gravity>
      <self_collide>false</self_collide>
      <velocity_decay/>
      <pose>0.212 -0.212 0.058 0 0 0</pose>
      <inertial>
          <mass>0.0128</mass>
          <inertia>
            <ixx>0.000015831</ixx>
            <iyy>0.000015843</iyy>
            <izz>0.000031494</izz>
          </inertia>
      </inertial>
      <enable_wind>true</enable_wind>
      <visual name="rotor_0_visual">
        <pose>0 0 0 0 0 0</pose>
        <geometry>
          <mesh>
            <scale>1 1 1</scale>
            <uri>model://phobos/meshes/ccw_prop.stl</uri>
          </mesh>
        </geometry>
        <material>
          <script>
            <name>Gazebo/DarkGrey</name>
            <uri>file://media/materials/scripts/gazebo.material</uri>
          </script>
        </material>
      </visual>
      <collision name="rotor_0_collision">
        <pose>0 0 0 0 0 0</pose>
        <geometry>
          <mesh>
            <scale>1 1 1</scale>
            <uri>model://phobos/meshes/ccw_prop.stl</uri>
          </mesh>
        </geometry>
        <surface>
          <contact>
            <ode>
              <kp>100000</kp>
              <kd>1.0</kd>
              <max_vel>0.1</max_vel>
              <min_depth>0.001</min_depth>
            </ode>
          </contact>
          <friction>
            <ode/>
          </friction>
        </surface>
      </collision>
    </link>
    <joint name="rotor_0_joint" type="revolute">
      <parent>base_link</parent>
      <child>rotor_0</child>
      <axis>
        <xyz>0 0 1</xyz>
        <limit>
          <lower>-1e+16</lower>
          <upper>1e+16</upper>
        </limit>
        <dynamics>
          <spring_reference>0</spring_reference>
          <spring_stiffness>0</spring_stiffness>
        </dynamics>
      </axis>
    </joint>
    <link name="rotor_1">
      <gravity>true</gravity>
      <self_collide>false</self_collide>
      <velocity_decay/>
      <pose>0.212 0.212 0.058 0 0 0</pose>
      <inertial>
          <mass>0.0128</mass>
          <inertia>
            <ixx>0.000015831</ixx>
            <iyy>0.000015843</iyy>
            <izz>0.000031494</izz>
          </inertia>
      </inertial>
      <enable_wind>true</enable_wind>
      <visual name="rotor_1_visual">
        <pose>0 0 0 0 0 0</pose>
        <geometry>
          <mesh>
            <scale>1 1 1</scale>
            <uri>model://phobos/meshes/cw_prop.stl</uri>
          </mesh>
        </geometry>
        <material>
          <script>
            <name>Gazebo/DarkGrey</name>
            <uri>file://media/materials/scripts/gazebo.material</uri>
          </script>
        </material>
      </visual>
      <collision name="rotor_1_collision">
        <pose>0 0 0 0 0 0</pose>
        <geometry>
          <mesh>
            <scale>1 1 1</scale>
            <uri>model://phobos/meshes/cw_prop.stl</uri>
          </mesh>
        </geometry>
        <surface>
          <contact>
            <ode>
              <kp>100000</kp>
              <kd>1.0</kd>
              <max_vel>0.1</max_vel>
              <min_depth>0.001</min_depth>
            </ode>
          </contact>
          <friction>
            <ode/>
          </friction>
        </surface>
      </collision>
    </link>
    <joint name="rotor_1_joint" type="revolute">
      <parent>base_link</parent>
      <child>rotor_1</child>
      <axis>
        <xyz>0 0 1</xyz>
        <limit>
          <lower>-1e+16</lower>
          <upper>1e+16</upper>
        </limit>
        <dynamics>
          <spring_reference>0</spring_reference>
          <spring_stiffness>0</spring_stiffness>
        </dynamics>
      </axis>
    </joint>
    <link name="rotor_2">
      <gravity>true</gravity>
      <self_collide>false</self_collide>
      <velocity_decay/>
      <pose>-0.212 0.212 0.058 0 0 0</pose>
      <inertial>
          <mass>0.0128</mass>
          <inertia>
            <ixx>0.000015831</ixx>
            <iyy>0.000015843</iyy>
            <izz>0.000031494</izz>
          </inertia>
      </inertial>
      <enable_wind>true</enable_wind>
      <visual name="rotor_2_visual">
        <pose>0 0 0 0 0 0</pose>
        <geometry>
          <mesh>
            <scale>1 1 1</scale>
            <uri>model://phobos/meshes/ccw_prop.stl</uri>
          </mesh>
        </geometry>
        <material>
          <script>
            <name>Gazebo/DarkGrey</name>
            <uri>file://media/materials/scripts/gazebo.material</uri>
          </script>
        </material>
      </visual>
      <collision name="rotor_2_collision">
        <pose>0 0 0 0 0 0</pose>
        <geometry>
          <mesh>
            <scale>1 1 1</scale>
            <uri>model://phobos/meshes/ccw_prop.stl</uri>
          </mesh>
        </geometry>
        <surface>
          <contact>
            <ode>
              <kp>100000</kp>
              <kd>1.0</kd>
              <max_vel>0.1</max_vel>
              <min_depth>0.001</min_depth>
            </ode>
          </contact>
          <friction>
            <ode/>
          </friction>
        </surface>
      </collision>
    </link>
    <joint name="rotor_2_joint" type="revolute">
      <parent>base_link</parent>
      <child>rotor_2</child>
      <axis>
        <xyz>0 0 1</xyz>
        <limit>
          <lower>-1e+16</lower>
          <upper>1e+16</upper>
        </limit>
        <dynamics>
          <spring_reference>0</spring_reference>
          <spring_stiffness>0</spring_stiffness>
        </dynamics>
      </axis>
    </joint>
    <link name="rotor_3">
      <gravity>true</gravity>
      <self_collide>false</self_collide>
      <velocity_decay/>
      <pose>-0.212 -0.212 0.058 0 0 0</pose>
      <inertial>
          <mass>0.0128</mass>
          <inertia>
            <ixx>0.000015831</ixx>
            <iyy>0.000015843</iyy>
            <izz>0.000031494</izz>
          </inertia>
      </inertial>
      <enable_wind>true</enable_wind>
      <visual name="rotor_3_visual">
        <pose>0 0 0 0 0 0</pose>
        <geometry>
          <mesh>
            <scale>1 1 1</scale>
            <uri>model://phobos/meshes/cw_prop.stl</uri>
          </mesh>
        </geometry>
        <material>
          <script>
            <name>Gazebo/DarkGrey</name>
            <uri>file://media/materials/scripts/gazebo.material</uri>
          </script>
        </material>
      </visual>
      <collision name="rotor_3_collision">
        <pose>0 0 0 0 0 0</pose>
        <geometry>
          <mesh>
            <scale>1 1 1</scale>
            <uri>model://phobos/meshes/cw_prop.stl</uri>
          </mesh>
        </geometry>
        <surface>
          <contact>
            <ode>
              <kp>100000</kp>
              <kd>1.0</kd>
              <max_vel>0.1</max_vel>
              <min_depth>0.001</min_depth>
            </ode>
          </contact>
          <friction>
            <ode/>
          </friction>
        </surface>
      </collision>
    </link>
    <joint name="rotor_3_joint" type="revolute">
      <parent>base_link</parent>
      <child>rotor_3</child>
      <axis>
        <xyz>0 0 1</xyz>
        <limit>
          <lower>-1e+16</lower>
          <upper>1e+16</upper>
        </limit>
        <dynamics>
          <spring_reference>0</spring_reference>
          <spring_stiffness>0</spring_stiffness>
        </dynamics>
      </axis>
    </joint>
    <link name="rotor_4">
      <gravity>true</gravity>
      <self_collide>false</self_collide>
      <velocity_decay/>
      <pose>0.212 0.212 -0.035 0 0 0</pose>
      <inertial>
          <mass>0.0128</mass>
          <inertia>
            <ixx>0.000015831</ixx>
            <iyy>0.000015843</iyy>
            <izz>0.000031494</izz>
          </inertia>
      </inertial>
      <enable_wind>true</enable_wind>
      <visual name="rotor_4_visual">
        <pose>0 0 0 0 0 0</pose>
        <geometry>
          <mesh>
            <scale>1 1 1</scale>
            <uri>model://phobos/meshes/ccw_prop.stl</uri>
          </mesh>
        </geometry>
        <material>
          <script>
            <name>Gazebo/DarkGrey</name>
            <uri>file://media/materials/scripts/gazebo.material</uri>
          </script>
        </material>
      </visual>
      <collision name="rotor_4_collision">
        <pose>0 0 0 0 0 0</pose>
        <geometry>
          <mesh>
            <scale>1 1 1</scale>
            <uri>model://phobos/meshes/ccw_prop.stl</uri>
          </mesh>
        </geometry>
        <surface>
          <contact>
            <ode>
              <kp>100000</kp>
              <kd>1.0</kd>
              <max_vel>0.1</max_vel>
              <min_depth>0.001</min_depth>
            </ode>
          </contact>
          <friction>
            <ode/>
          </friction>
        </surface>
      </collision>
    </link>
    <joint name="rotor_4_joint" type="revolute">
      <parent>base_link</parent>
      <child>rotor_4</child>
      <axis>
        <xyz>0 0 1</xyz>
        <limit>
          <lower>-1e+16</lower>
          <upper>1e+16</upper>
        </limit>
        <dynamics>
          <spring_reference>0</spring_reference>
          <spring_stiffness>0</spring_stiffness>
        </dynamics>
      </axis>
    </joint>
    <link name="rotor_5">
      <gravity>true</gravity>
      <self_collide>false</self_collide>
      <velocity_decay/>
      <pose>0.212 -0.212 -0.035 0 0 0</pose>
      <inertial>
          <mass>0.0128</mass>
          <inertia>
            <ixx>0.000015831</ixx>
            <iyy>0.000015843</iyy>
            <izz>0.000031494</izz>
          </inertia>
      </inertial>
      <enable_wind>true</enable_wind>
      <visual name="rotor_5_visual">
        <pose>0 0 0 0 0 0</pose>
        <geometry>
          <mesh>
            <scale>1 1 1</scale>
            <uri>model://phobos/meshes/cw_prop.stl</uri>
          </mesh>
        </geometry>
        <material>
          <script>
            <name>Gazebo/DarkGrey</name>
            <uri>file://media/materials/scripts/gazebo.material</uri>
          </script>
        </material>
      </visual>
      <collision name="rotor_5_collision">
        <pose>0 0 0 0 0 0</pose>
        <geometry>
          <mesh>
            <scale>1 1 1</scale>
            <uri>model://phobos/meshes/cw_prop.stl</uri>
          </mesh>
        </geometry>
        <surface>
          <contact>
            <ode>
              <kp>100000</kp>
              <kd>1.0</kd>
              <max_vel>0.1</max_vel>
              <min_depth>0.001</min_depth>
            </ode>
          </contact>
          <friction>
            <ode/>
          </friction>
        </surface>
      </collision>
    </link>
    <joint name="rotor_5_joint" type="revolute">
      <parent>base_link</parent>
      <child>rotor_5</child>
      <axis>
        <xyz>0 0 1</xyz>
        <limit>
          <lower>-1e+16</lower>
          <upper>1e+16</upper>
        </limit>
        <dynamics>
          <spring_reference>0</spring_reference>
          <spring_stiffness>0</spring_stiffness>
        </dynamics>
      </axis>
    </joint>
    <link name="rotor_6">
      <gravity>true</gravity>
      <self_collide>false</self_collide>
      <velocity_decay/>
      <pose>-0.212 -0.212 -0.035 0 0 0</pose>
      <inertial>
          <mass>0.0128</mass>
          <inertia>
            <ixx>0.000015831</ixx>
            <iyy>0.000015843</iyy>
            <izz>0.000031494</izz>
          </inertia>
      </inertial>
      <enable_wind>true</enable_wind>
      <visual name="rotor_6_visual">
        <pose>0 0 0 0 0 0</pose>
        <geometry>
          <mesh>
            <scale>1 1 1</scale>
            <uri>model://phobos/meshes/ccw_prop.stl</uri>
          </mesh>
        </geometry>
        <material>
          <script>
            <name>Gazebo/DarkGrey</name>
            <uri>file://media/materials/scripts/gazebo.material</uri>
          </script>
        </material>
      </visual>
      <collision name="rotor_6_collision">
        <pose>0 0 0 0 0 0</pose>
        <geometry>
          <mesh>
            <scale>1 1 1</scale>
            <uri>model://phobos/meshes/ccw_prop.stl</uri>
          </mesh>
        </geometry>
        <surface>
          <contact>
            <ode>
              <kp>100000</kp>
              <kd>1.0</kd>
              <max_vel>0.1</max_vel>
              <min_depth>0.001</min_depth>
            </ode>
          </contact>
          <friction>
            <ode/>
          </friction>
        </surface>
      </collision>
    </link>
    <joint name="rotor_6_joint" type="revolute">
      <parent>base_link</parent>
      <child>rotor_6</child>
      <axis>
        <xyz>0 0 1</xyz>
        <limit>
          <lower>-1e+16</lower>
          <upper>1e+16</upper>
        </limit>
        <dynamics>
          <spring_reference>0</spring_reference>
          <spring_stiffness>0</spring_stiffness>
        </dynamics>
      </axis>
    </joint>
    <link name="rotor_7">
      <gravity>true</gravity>
      <self_collide>false</self_collide>
      <velocity_decay/>
      <pose>-0.212 0.212 -0.035 0 0 0</pose>
      <inertial>
          <mass>0.0128</mass>
          <inertia>
            <ixx>0.000015831</ixx>
            <iyy>0.000015843</iyy>
            <izz>0.000031494</izz>
          </inertia>
      </inertial>
      <enable_wind>true</enable_wind>
      <visual name="rotor_7_visual">
        <pose>0 0 0 0 0 0</pose>
        <geometry>
          <mesh>
            <scale>1 1 1</scale>
            <uri>model://phobos/meshes/cw_prop.stl</uri>
          </mesh>
        </geometry>
        <material>
          <script>
            <name>Gazebo/DarkGrey</name>
            <uri>file://media/materials/scripts/gazebo.material</uri>
          </script>
        </material>
      </visual>
      <collision name="rotor_7_collision">
        <pose>0 0 0 0 0 0</pose>
        <geometry>
          <mesh>
            <scale>1 1 1</scale>
            <uri>model://phobos/meshes/cw_prop.stl</uri>
          </mesh>
        </geometry>
        <surface>
          <contact>
            <ode>
              <kp>100000</kp>
              <kd>1.0</kd>
              <max_vel>0.1</max_vel>
              <min_depth>0.001</min_depth>
            </ode>
          </contact>
          <friction>
            <ode/>
          </friction>
        </surface>
      </collision>
    </link>
    <joint name="rotor_7_joint" type="revolute">
      <parent>base_link</parent>
      <child>rotor_7</child>
      <axis>
        <xyz>0 0 1</xyz>
        <limit>
          <lower>-1e+16</lower>
          <upper>1e+16</upper>
        </limit>
        <dynamics>
          <spring_reference>0</spring_reference>
          <spring_stiffness>0</spring_stiffness>
        </dynamics>
      </axis>
    </joint>
    <plugin filename="gz-sim-multicopter-motor-model-system" name="gz::sim::systems::MulticopterMotorModel">
      <jointName>rotor_0_joint</jointName>
      <linkName>rotor_0</linkName>
      <turningDirection>ccw</turningDirection>
      <timeConstantUp>0.0125</timeConstantUp>
      <timeConstantDown>0.025</timeConstantDown>
      <maxRotVelocity>17668</maxRotVelocity>
      <motorConstant>2.6e-05</motorConstant>
      <momentConstant>0.016</momentConstant>
      <commandSubTopic>command/motor_speed</commandSubTopic>
      <motorNumber>0</motorNumber>
      <rotorDragCoefficient>8.06428e-06</rotorDragCoefficient>
      <rollingMomentCoefficient>1e-06</rollingMomentCoefficient>
      <rotorVelocitySlowdownSim>10</rotorVelocitySlowdownSim>
      <motorType>velocity</motorType>
    </plugin>
    <plugin filename="gz-sim-multicopter-motor-model-system" name="gz::sim::systems::MulticopterMotorModel">
      <jointName>rotor_1_joint</jointName>
      <linkName>rotor_1</linkName>
      <turningDirection>cw</turningDirection>
      <timeConstantUp>0.0125</timeConstantUp>
      <timeConstantDown>0.025</timeConstantDown>
      <maxRotVelocity>17668</maxRotVelocity>
      <motorConstant>2.6e-05</motorConstant>
      <momentConstant>0.016</momentConstant>
      <commandSubTopic>command/motor_speed</commandSubTopic>
      <motorNumber>1</motorNumber>
      <rotorDragCoefficient>8.06428e-06</rotorDragCoefficient>
      <rollingMomentCoefficient>1e-06</rollingMomentCoefficient>
      <rotorVelocitySlowdownSim>10</rotorVelocitySlowdownSim>
      <motorType>velocity</motorType>
    </plugin>
    <plugin filename="gz-sim-multicopter-motor-model-system" name="gz::sim::systems::MulticopterMotorModel">
      <jointName>rotor_2_joint</jointName>
      <linkName>rotor_2</linkName>
      <turningDirection>ccw</turningDirection>
      <timeConstantUp>0.0125</timeConstantUp>
      <timeConstantDown>0.025</timeConstantDown>
      <maxRotVelocity>17668</maxRotVelocity>
      <motorConstant>2.6e-05</motorConstant>
      <momentConstant>0.016</momentConstant>
      <commandSubTopic>command/motor_speed</commandSubTopic>
      <motorNumber>2</motorNumber>
      <rotorDragCoefficient>8.06428e-06</rotorDragCoefficient>
      <rollingMomentCoefficient>1e-06</rollingMomentCoefficient>
      <rotorVelocitySlowdownSim>10</rotorVelocitySlowdownSim>
      <motorType>velocity</motorType>
    </plugin>
    <plugin filename="gz-sim-multicopter-motor-model-system" name="gz::sim::systems::MulticopterMotorModel">
      <jointName>rotor_3_joint</jointName>
      <linkName>rotor_3</linkName>
      <turningDirection>cw</turningDirection>
      <timeConstantUp>0.0125</timeConstantUp>
      <timeConstantDown>0.025</timeConstantDown>
      <maxRotVelocity>17668</maxRotVelocity>
      <motorConstant>2.6e-05</motorConstant>
      <momentConstant>0.016</momentConstant>
      <commandSubTopic>command/motor_speed</commandSubTopic>
      <motorNumber>3</motorNumber>
      <rotorDragCoefficient>8.06428e-06</rotorDragCoefficient>
      <rollingMomentCoefficient>1e-06</rollingMomentCoefficient>
      <rotorVelocitySlowdownSim>10</rotorVelocitySlowdownSim>
      <motorType>velocity</motorType>
    </plugin>
    <plugin filename="gz-sim-multicopter-motor-model-system" name="gz::sim::systems::MulticopterMotorModel">
      <jointName>rotor_4_joint</jointName>
      <linkName>rotor_4</linkName>
      <turningDirection>ccw</turningDirection>
      <timeConstantUp>0.0125</timeConstantUp>
      <timeConstantDown>0.025</timeConstantDown>
      <maxRotVelocity>17668</maxRotVelocity>
      <motorConstant>2.6e-05</motorConstant>
      <momentConstant>0.016</momentConstant>
      <commandSubTopic>command/motor_speed</commandSubTopic>
      <motorNumber>4</motorNumber>
      <rotorDragCoefficient>8.06428e-06</rotorDragCoefficient>
      <rollingMomentCoefficient>1e-06</rollingMomentCoefficient>
      <rotorVelocitySlowdownSim>10</rotorVelocitySlowdownSim>
      <motorType>velocity</motorType>
    </plugin>
    <plugin filename="gz-sim-multicopter-motor-model-system" name="gz::sim::systems::MulticopterMotorModel">
      <jointName>rotor_5_joint</jointName>
      <linkName>rotor_5</linkName>
      <turningDirection>cw</turningDirection>
      <timeConstantUp>0.0125</timeConstantUp>
      <timeConstantDown>0.025</timeConstantDown>
      <maxRotVelocity>17668</maxRotVelocity>
      <motorConstant>2.6e-05</motorConstant>
      <momentConstant>0.016</momentConstant>
      <commandSubTopic>command/motor_speed</commandSubTopic>
      <motorNumber>5</motorNumber>
      <rotorDragCoefficient>8.06428e-06</rotorDragCoefficient>
      <rollingMomentCoefficient>1e-06</rollingMomentCoefficient>
      <rotorVelocitySlowdownSim>10</rotorVelocitySlowdownSim>
      <motorType>velocity</motorType>
    </plugin>
    <plugin filename="gz-sim-multicopter-motor-model-system" name="gz::sim::systems::MulticopterMotorModel">
      <jointName>rotor_6_joint</jointName>
      <linkName>rotor_6</linkName>
      <turningDirection>ccw</turningDirection>
      <timeConstantUp>0.0125</timeConstantUp>
      <timeConstantDown>0.025</timeConstantDown>
      <maxRotVelocity>17668</maxRotVelocity>
      <motorConstant>2.6e-05</motorConstant>
      <momentConstant>0.016</momentConstant>
      <commandSubTopic>command/motor_speed</commandSubTopic>
      <motorNumber>6</motorNumber>
      <rotorDragCoefficient>8.06428e-06</rotorDragCoefficient>
      <rollingMomentCoefficient>1e-06</rollingMomentCoefficient>
      <rotorVelocitySlowdownSim>10</rotorVelocitySlowdownSim>
      <motorType>velocity</motorType>
    </plugin>
    <plugin filename="gz-sim-multicopter-motor-model-system" name="gz::sim::systems::MulticopterMotorModel">
      <jointName>rotor_7_joint</jointName>
      <linkName>rotor_7</linkName>
      <turningDirection>cw</turningDirection>
      <timeConstantUp>0.0125</timeConstantUp>
      <timeConstantDown>0.025</timeConstantDown>
      <maxRotVelocity>17668</maxRotVelocity>
      <motorConstant>2.6e-05</motorConstant>
      <momentConstant>0.016</momentConstant>
      <commandSubTopic>command/motor_speed</commandSubTopic>
      <motorNumber>7</motorNumber>
      <rotorDragCoefficient>8.06428e-06</rotorDragCoefficient>
      <rollingMomentCoefficient>1e-06</rollingMomentCoefficient>
      <rotorVelocitySlowdownSim>10</rotorVelocitySlowdownSim>
      <motorType>velocity</motorType>
    </plugin>
    <plugin
      filename="gz-sim-odometry-publisher-system"
      name="gz::sim::systems::OdometryPublisher">
      <odom_frame>map</odom_frame>
      <robot_base_frame>base_link</robot_base_frame>
      <odom_topic>odom</odom_topic>
      <dimensions>3</dimensions>
    </plugin>
    </model>
</sdf>
